<?xml version="1.0" encoding="utf-8"?>
<!-- This URDF was automatically created by SolidWorks to URDF Exporter! Originally created by Stephen Brawner (brawner@gmail.com) 
     Commit Version: 1.5.1-0-g916b5db  Build Version: 1.5.7152.31018
     For more information, please see http://wiki.ros.org/sw_urdf_exporter -->
<robot
  name="FullMech_Rep">
  <link
    name="drivetrain">
    <inertial>
      <origin
        xyz="0.427967702655067 -1.2478399767059E-18 0.115370408915359"
        rpy="0 0 0" />
      <mass
        value="3.77582130485992" />
      <inertia
        ixx="0.0534389873542028"
        ixy="-8.6678466130766E-17"
        ixz="-0.000464379665206139"
        iyy="0.321833554389598"
        iyz="-2.26109654584817E-18"
        izz="0.373546703309241" />
    </inertial>
    <visual>
      <origin
        xyz="0 0 0"
        rpy="0 0 0" />
      <geometry>
        <mesh
          filename="package://FullMech_Rep/meshes/drivetrain.STL" />
      </geometry>
      <material
        name="">
        <color
          rgba="0.792156862745098 0.819607843137255 0.933333333333333 1" />
      </material>
    </visual>
    <collision>
      <origin
        xyz="0 0 0"
        rpy="0 0 0" />
      <geometry>
        <mesh
          filename="package://FullMech_Rep/meshes/drivetrain.STL" />
      </geometry>
    </collision>
  </link>
  <link
    name="wheel1">
    <inertial>
      <origin
        xyz="2.03883021576701E-10 1.33968752757951E-10 0.00351465143708507"
        rpy="0 0 0" />
      <mass
        value="1.22527899288125" />
      <inertia
        ixx="0.00598133477433838"
        ixy="8.04814637676843E-10"
        ixz="5.66524331353205E-12"
        iyy="0.00598133797966457"
        iyz="7.67346880397323E-12"
        izz="0.0109596153406496" />
    </inertial>
    <visual>
      <origin
        xyz="0 0 0"
        rpy="0 0 0" />
      <geometry>
        <cylinder radius=".12" length="0.05"/>
        <!-- <mesh
          filename="package://FullMech_Rep/meshes/wheel1.STL" /> -->
      </geometry>
      <material
        name="">
        <color
          rgba="1 1 1 1" />
      </material>
    </visual>
    <collision>
      <origin
        xyz="0 0 0"
        rpy="0 0 0" />
      <geometry>
        <cylinder radius=".12" length="0.05"/>
        <!-- <mesh
          filename="package://FullMech_Rep/meshes/wheel1.STL" /> -->
      </geometry>
    </collision>
  </link>
  <joint
    name="axle1"
    type="continuous">
    <origin
      xyz="0.15 -0.18271 0.115"
      rpy="1.5708 -0.53093 3.14" />
    <parent
      link="drivetrain" />
    <child
      link="wheel1" />
    <axis
      xyz="0 0 1" />
    <!-- <limit
      effort="5"
      velocity="0.25" /> -->
  </joint>
  <link
    name="wheel2">
    <inertial>
      <origin
        xyz="-1.34570687926328E-10 1.89999876942792E-10 0.00351465143708507"
        rpy="0 0 0" />
      <mass
        value="1.22527899288124" />
      <inertia
        ixx="0.00598133445312605"
        ixy="4.08741008053881E-10"
        ixz="-7.13003401965768E-10"
        iyy="0.00598133605794787"
        iyz="1.93637321583713E-10"
        izz="0.0109596137019381" />
    </inertial>
    <visual>
      <origin
        xyz="0 0 0"
        rpy="0 0 0" />
      <geometry>
        <cylinder radius=".12" length="0.05"/>
        <!-- <mesh
          filename="package://FullMech_Rep/meshes/wheel1.STL" /> -->
      </geometry>
      <material
        name="">
        <color
          rgba="1 1 1 1" />
      </material>
    </visual>
    <collision>
      <origin
        xyz="0 0 0"
        rpy="0 0 0" />
      <geometry>
        <cylinder radius=".12" length="0.05"/>
        <!-- <mesh
          filename="package://FullMech_Rep/meshes/wheel1.STL" /> -->
      </geometry>
    </collision>
  </link>
  <joint
    name="axle2"
    type="continuous">
    <origin
      xyz="0.15 0.18271 0.115"
      rpy="1.5708 0.74348 3.1416" />
    <parent
      link="drivetrain" />
    <child
      link="wheel2" />
    <axis
      xyz="0 0 1" />
    <!-- <limit
      effort="5"
      velocity="0.25" /> -->
  </joint>
  <link
    name="wheel3">
    <inertial>
      <origin
        xyz="1.14839249221177E-11 -3.22153193010877E-10 0.0035146514370851"
        rpy="0 0 0" />
      <mass
        value="1.22527899288124" />
      <inertia
        ixx="0.00598133477451402"
        ixy="8.04836569568909E-10"
        ixz="6.52449869496267E-12"
        iyy="0.00598133797959156"
        iyz="-2.81196609749864E-11"
        izz="0.0109596153407522" />
    </inertial>
    <visual>
      <origin
        xyz="0 0 0"
        rpy="0 0 0" />
      <geometry>
        <cylinder radius=".12" length="0.05"/>
        <!-- <mesh
          filename="package://FullMech_Rep/meshes/wheel1.STL" /> -->
      </geometry>
      <material
        name="">
        <color
          rgba="1 1 1 1" />
      </material>
    </visual>
    <collision>
      <origin
        xyz="0 0 0"
        rpy="0 0 0" />
      <geometry>
        <cylinder radius=".12" length="0.05"/>
        <!-- <mesh
          filename="package://FullMech_Rep/meshes/wheel1.STL" /> -->
      </geometry>
    </collision>
  </link>
  <joint
    name="axle3"
    type="continuous">
    <origin
      xyz="0.7 0.18271 0.115"
      rpy="1.5708 0.90647 3.1416" />
    <parent
      link="drivetrain" />
    <child
      link="wheel3" />
    <axis
      xyz="0 0 1" />
    <!-- <limit
      effort="5"
      velocity="0.25" /> -->
  </joint>
  <link
    name="wheel4">
    <inertial>
      <origin
        xyz="2.03883021576701E-10 1.33968725002376E-10 0.00351465143708507"
        rpy="0 0 0" />
      <mass
        value="1.22527899288125" />
      <inertia
        ixx="0.00598133477433839"
        ixy="8.04814633773715E-10"
        ixz="5.66524755653519E-12"
        iyy="0.00598133797966457"
        iyz="7.6734696431667E-12"
        izz="0.0109596153406496" />
    </inertial>
    <visual>
      <origin
        xyz="0 0 0"
        rpy="0 0 0" />
      <geometry>
        <cylinder radius=".12" length="0.05"/>
        <!-- <mesh
          filename="package://FullMech_Rep/meshes/wheel1.STL" /> -->
      </geometry>
      <material
        name="">
        <color
          rgba="1 1 1 1" />
      </material>
    </visual>
    <collision>
      <origin
        xyz="0 0 0"
        rpy="0 0 0" />
     <geometry>
        <cylinder radius=".12" length="0.05"/>
        <!-- <mesh
          filename="package://FullMech_Rep/meshes/wheel1.STL" /> -->
      </geometry>
    </collision>
  </link>
  <joint
    name="axle4"
    type="continuous">
    <origin
      xyz="0.7 -0.18271 0.115"
      rpy="1.5708 -0.53093 3.14" />
    <parent
      link="drivetrain" />
    <child
      link="wheel4" />
    <axis
      xyz="0 0 1" />
    <!-- <limit
      effort="5"
      velocity="0.25" /> -->
  </joint>
  <link
    name="storage">
    <inertial>
      <origin
        xyz="0.175 -1.15558955938244E-16 0.425714894314765"
        rpy="0 0 0" />
      <mass value=".01"/>
      <!-- <mass value="0.248919999999999" /> -->
      <inertia
        ixx="0.00162641116102266"
        ixy="7.96540095890137E-22"
        ixz="1.98679070880409E-19"
        iyy="0.00416733566666664"
        iyz="-5.53862670426238E-23"
        izz="0.00254119216102265" />
    </inertial>
    <visual>
      <origin
        xyz="0 0 0"
        rpy="0 0 0" />
      <geometry>
        <mesh
          filename="package://FullMech_Rep/meshes/storage.STL" />
      </geometry>
      <material
        name="">
        <color
          rgba="0.792156862745098 0.819607843137255 0.933333333333333 1" />
      </material>
    </visual>
    <collision>
      <origin
        xyz="0 0 0"
        rpy="0 0 0" />
      <geometry>
        <mesh
          filename="package://FullMech_Rep/meshes/storage.STL" />
      </geometry>
    </collision>
  </link>
  <joint
    name="scissor"
    type="prismatic">
    <origin
      xyz="0 0 0"
      rpy="0 0 0" />
    <parent
      link="drivetrain" />
    <child
      link="storage" />
    <axis
      xyz="0 0 1" />
    <limit
      lower="-0.3"
      upper="0.1"
      effort="5"
      velocity="0.25" />
  </joint>
  <link
    name="dispense_rotate">
    <inertial>
      <origin
        xyz="-0.0107846080095739 0.118085027911473 1.32411686714264E-16"
        rpy="0 0 0" />
      <mass value=".01"/>
      <!-- <mass value="0.490259886128" /> -->
      <inertia
        ixx="0.00778343636692995"
        ixy="-0.00266036642706346"
        ixz="-4.65078212371813E-18"
        iyy="0.00957311492456416"
        iyz="-9.76585077897691E-20"
        izz="0.00657647247964353" />
    </inertial>
    <visual>
      <origin
        xyz="0 0 0"
        rpy="0 0 0" />
      <geometry>
        <mesh
          filename="package://FullMech_Rep/meshes/dispense_rotate.STL" />
      </geometry>
      <material
        name="">
        <color
          rgba="0.792156862745098 0.819607843137255 0.933333333333333 1" />
      </material>
    </visual>
    <collision>
      <origin
        xyz="0 0 0"
        rpy="0 0 0" />
      <geometry>
        <mesh
          filename="package://FullMech_Rep/meshes/dispense_rotate.STL" />
      </geometry>
    </collision>
  </link>
  <joint
    name="dispense_rotate"
    type="revolute">
    <origin
      xyz="0.175 0 0.42444"
      rpy="1.5708 0 0" />
    <parent
      link="storage" />
    <child
      link="dispense_rotate" />
    <axis
      xyz="0 0 -1" />
    <limit
      lower="0"
      upper="1.05"
      effort="5"
      velocity="0.8" />
  </joint>
  <link
    name="rotate_conv">
    <inertial>
      <origin
        xyz="-1.94289029309402E-16 -1.11022302462516E-16 0.1"
        rpy="0 0 0" />
      <mass value=".01"/>
      <!-- <mass
        value="4.12035499957539" /> -->
      <inertia
        ixx="0.0504951827564745"
        ixy="0.0155266647555281"
        ixz="-2.61944938938392E-16"
        iyy="0.0598724883705849"
        iyz="8.57197342621352E-16"
        izz="0.0547695583840302" />
    </inertial>
    <visual>
      <origin
        xyz="0 0 0"
        rpy="0 0 0" />
      <geometry>
        <mesh
          filename="package://FullMech_Rep/meshes/rotate_conv.STL" />
      </geometry>
      <material
        name="">
        <color
          rgba="0.792156862745098 0.819607843137255 0.933333333333333 1" />
      </material>
    </visual>
    <collision>
      <origin
        xyz="0 0 0"
        rpy="0 0 0" />
      <geometry>
        <mesh
          filename="package://FullMech_Rep/meshes/rotate_conv.STL" />
      </geometry>
    </collision>
  </link>
  <joint
    name="rotate"
    type="revolute">
    <origin
      xyz="0.73794 0.1 0.22326"
      rpy="1.5708 1.2662 0" />
    <parent
      link="drivetrain" />
    <child
      link="rotate_conv" />
    <axis
      xyz="0 0 1" />
    <limit
      lower="0.384"
      upper="1.25"
      effort="5"
      velocity="0.5" />
  </joint>
  <link
    name="translation">
    <inertial>
      <origin
        xyz="0.737944768013426 -1.29757316003065E-15 0.223255983183746"
        rpy="0 0 0" />
      <mass value=".01"/>
      <!-- <mass
        value="4.12035499957539" /> -->
      <inertia
        ixx="0.0504951827564745"
        ixy="0.0155266647555281"
        ixz="-2.61309664227952E-16"
        iyy="0.0598724883705849"
        iyz="8.58044375568606E-16"
        izz="0.0547695583840302" />
    </inertial>
    <visual>
      <origin
        xyz="0 0 0"
        rpy="0 0 0" />
      <geometry>
        <mesh
          filename="package://FullMech_Rep/meshes/translation.STL" />
      </geometry>
      <material
        name="">
        <color
          rgba="0.792156862745098 0.819607843137255 0.933333333333333 1" />
      </material>
    </visual>
    <collision>
      <origin
        xyz="0 0 0"
        rpy="0 0 0" />
      <geometry>
        <mesh
          filename="package://FullMech_Rep/meshes/translation.STL" />
      </geometry>
    </collision>
  </link>
  <joint
    name="rack"
    type="prismatic">
    <origin
      xyz="-0.0083328 -0.77093 0.1"
      rpy="-1.5708 0 1.2662" />
    <parent
      link="rotate_conv" />
    <child
      link="translation" />
    <axis
      xyz="-0.2999 0 0.95397" />
    <limit
      lower="-0.5"
      upper="0.0"
      effort="5"
      velocity="0.25" />
  </joint>

  <!-- Link for laser scanner -->
  <link name="sensor_laser">
    <inertial>
        <origin xyz="0 0 0" rpy="0 0 0" />
        <mass value="1" />
        <inertia
        ixx="0.00598133477437682"
        ixy="8.04804660631611E-10"
        ixz="-1.37907950166563E-12"
        iyy="0.00598133797963134"
        iyz="-1.53294491952911E-11"
        izz="0.0109596153406548" />
    </inertial>

    <visual>
        <origin xyz="0 0 0" rpy="0 0 0" />
        <geometry>
          <cylinder radius="0.05" length="0.05"/>
        </geometry>
        <material name="white" />
    </visual>

    <collision>
        <origin xyz="0 0 0" rpy="0 0 0"/>
        <geometry>
        <cylinder radius="0.05" length="0.1"/>
        </geometry>
    </collision>
  </link>

  <!-- Joint to attach the laser scanner to the drivetrain -->
  <joint name="joint_sensor_laser" type="fixed">
    <origin xyz="1.05 0 0.5" rpy="0 0.0 0.0"/>
    <parent link="drivetrain"/>
    <child link="sensor_laser"/>
  </joint>

  <!-- Gazebo plugin for the laser scanner -->
  <gazebo reference="sensor_laser">
    <sensor type="ray" name="head_hokuyo_sensor">
      <pose>0 0 0 0 0 0</pose>
      <visualize>false</visualize>
      <update_rate>20</update_rate>
      <ray>
        <scan>
          <horizontal>
            <samples>720</samples>
            <resolution>1</resolution>
            <min_angle>-1.570796</min_angle>
            <max_angle>1.570796</max_angle>
          </horizontal>
        </scan>
        <range>
          <min>0.10</min>
          <max>10.0</max>
          <resolution>0.01</resolution>
        </range>
        <noise>
          <type>gaussian</type>
          <mean>0.0</mean>
          <stddev>0.01</stddev>
        </noise>
      </ray>
      <plugin name="gazebo_ros_head_hokuyo_controller" filename="libgazebo_ros_laser.so">
        <topicName>/laser_scan</topicName>
        <frameName>sensor_laser</frameName>
      </plugin>
    </sensor>
  </gazebo>

   <!-- Camera -->
  <link name="camera_link">
    <collision>
      <origin xyz="0 0 0" rpy="0 0 0"/>
      <geometry>
        <box size=".05 .05 .05"/>
      </geometry>
    </collision>

    <visual>
      <origin xyz="0 0 0" rpy="0 0 0"/>
      <geometry>
        <box size=".05 .05 .05"/>
      </geometry>
      <material name="red"/>
    </visual>

    <inertial>
      <mass value="1e-5" />
      <origin xyz="0 0 0" rpy="0 0 0"/>
      <inertia ixx="1e-6" ixy="0" ixz="0" iyy="1e-6" iyz="0" izz="1e-6" />
    </inertial>
  </link>

  <!-- Joint to attach camera to drivetrain -->
  <joint name="camera_joint" type="continuous">
    <axis xyz="0 0 1" />
    <origin xyz="0 0.2 0.45" rpy="0 0 3.14"/>
    <parent link="drivetrain"/>
    <child link="camera_link"/>
  </joint>

   <!-- gazebo camera -->
  <gazebo reference="camera_link">
    <sensor type="camera" name="camera1">
      <update_rate>30.0</update_rate>
      <camera name="head">
        <horizontal_fov>1.3962634</horizontal_fov>
        <image>
          <width>720</width>
          <height>480</height>
          <format>R8G8B8</format>
        </image>
        <clip>
          <near>0.02</near>
          <far>300</far>
        </clip>
        <noise>
          <type>gaussian</type>
          <!-- Noise is sampled independently per pixel on each frame.
               That pixel's noise value is added to each of its color
               channels, which at that point lie in the range [0,1]. -->
          <mean>0.0</mean>
          <stddev>0.007</stddev>
        </noise>
      </camera>
      <plugin name="camera_controller" filename="libgazebo_ros_camera.so">
        <alwaysOn>true</alwaysOn>
        <updateRate>0.0</updateRate>
        <cameraName>rmcbot/camera1</cameraName>
        <imageTopicName>image_raw</imageTopicName>
        <cameraInfoTopicName>camera_info</cameraInfoTopicName>
        <frameName>camera_link</frameName>
        <hackBaseline>0.07</hackBaseline>
        <distortionK1>0.0</distortionK1>
        <distortionK2>0.0</distortionK2>
        <distortionK3>0.0</distortionK3>
        <distortionT1>0.0</distortionT1>
        <distortionT2>0.0</distortionT2>
      </plugin>
    </sensor>
  </gazebo>

  <!-- Transmission for the camera rotation -->
  <transmission name="camera_rotate">
    <type>transmission_interface/SimpleTransmission</type>
    <actuator name="$camera_rotate_motor">
      <mechanicalReduction>1</mechanicalReduction>
    </actuator>
    <joint name="camera_joint">
      <hardwareInterface>PositionJointInterface</hardwareInterface>
    </joint>
  </transmission>

  <!-- Transmission for the end effector rotation -->
  <transmission name="end_effector_rotate">
    <type>transmission_interface/SimpleTransmission</type>
    <actuator name="$end_effector_rotate_motor">
      <mechanicalReduction>1</mechanicalReduction>
    </actuator>
    <joint name="rotate">
      <hardwareInterface>PositionJointInterface</hardwareInterface>
    </joint>
  </transmission>

  <!-- Transmission for the end effector rack -->
  <transmission name="end_effector_rack">
    <type>transmission_interface/SimpleTransmission</type>
    <actuator name="$end_effector_rack_motor">
      <mechanicalReduction>1</mechanicalReduction>
    </actuator>
    <joint name="rack">
      <hardwareInterface>PositionJointInterface</hardwareInterface>
    </joint>
  </transmission>

  <!-- Transmission for the dispensing scissor lift-->
  <transmission name="dispense_scissor">
    <type>transmission_interface/SimpleTransmission</type>
    <actuator name="$dispence_scissor_motor">
      <mechanicalReduction>1</mechanicalReduction>
    </actuator>
    <joint name="scissor">
      <hardwareInterface>PositionJointInterface</hardwareInterface>
    </joint>
  </transmission>

  <!-- Transmission for the dispensing dump -->
  <transmission name="dispense_dump">
    <type>transmission_interface/SimpleTransmission</type>
    <actuator name="$dispense_dump_motor">
      <mechanicalReduction>1</mechanicalReduction>
    </actuator>
    <joint name="dispense_rotate">
      <hardwareInterface>PositionJointInterface</hardwareInterface>
    </joint>
  </transmission>

  <!-- Transmissions for the 4 wheels -->
  <transmission name="wheel_1_trans">
      <type>transmission_interface/SimpleTransmission</type>
      <actuator name="$wheel_1_motor">
        <mechanicalReduction>1</mechanicalReduction>
      </actuator>
      <joint name="axle1">
        <hardwareInterface>VelocityJointInterface</hardwareInterface>
      </joint>
  </transmission>

  <transmission name="wheel_2_trans">
      <type>transmission_interface/SimpleTransmission</type>
      <actuator name="$wheel_2_motor">
        <mechanicalReduction>1</mechanicalReduction>
      </actuator>
      <joint name="axle2">
        <hardwareInterface>VelocityJointInterface</hardwareInterface>
      </joint>
  </transmission>

  <transmission name="wheel_3_trans">
      <type>transmission_interface/SimpleTransmission</type>
      <actuator name="$wheel_3_motor">
        <mechanicalReduction>1</mechanicalReduction>
      </actuator>
      <joint name="axle3">
        <hardwareInterface>VelocityJointInterface</hardwareInterface>
      </joint>
  </transmission>

  <transmission name="wheel_4_trans">
      <type>transmission_interface/SimpleTransmission</type>
      <actuator name="$wheel_4_motor">
        <mechanicalReduction>1</mechanicalReduction>
      </actuator>
      <joint name="axle4">
        <hardwareInterface>VelocityJointInterface</hardwareInterface>
      </joint>
  </transmission>

  <!-- Interaction properties of the wheels. Friction and such -->
  <gazebo reference="wheel1">
      <mu1 value="200.0"/>
      <mu2 value="100.0"/>
      <kp value="10000000.0" />
      <kd value="1.0" />
      <!-- <material>Gazebo/Grey</material> -->
  </gazebo>

  <gazebo reference="wheel2">
      <mu1 value="200.0"/>
      <mu2 value="100.0"/>
      <kp value="10000000.0" />
      <kd value="1.0" />
      <!-- <material>Gazebo/Grey</material> -->
  </gazebo>

  <gazebo reference="wheel3">
      <mu1 value="200.0"/>
      <mu2 value="100.0"/>
      <kp value="10000000.0" />
      <kd value="1.0" />
      <!-- <material>Gazebo/Grey</material> -->
  </gazebo>

  <gazebo reference="wheel4">
      <mu1 value="200.0"/>
      <mu2 value="100.0"/>
      <kp value="10000000.0" />
      <kd value="1.0" />
      <!-- <material>Gazebo/Grey</material> -->
  </gazebo>


  <!-- Gazebo plugin for ROS control -->
  <gazebo>
    <plugin name="gazebo_ros_control" filename="libgazebo_ros_control.so">
      <robotNamespace>/</robotNamespace>
    </plugin>
  </gazebo>
</robot>