<?xml version="1.0" encoding="utf-8"?>
<!-- This URDF was automatically created by SolidWorks to URDF Exporter! Originally created by Stephen Brawner (brawner@gmail.com) 
     Commit Version: 1.5.1-0-g916b5db  Build Version: 1.5.7152.31018
     For more information, please see http://wiki.ros.org/sw_urdf_exporter -->
<robot
  name="FullMech_Rep">
  <link
    name="drivetrain">
    <inertial>
      <origin
        xyz="0.427967702655067 0.115370408915359 0"
        rpy="0 0 0" />
      <mass
        value="3.77582130485992" />
      <inertia
        ixx="0.0534389873542028"
        ixy="-0.000464379665206139"
        ixz="8.4221937510363E-17"
        iyy="0.373546703309241"
        iyz="1.93690608670778E-18"
        izz="0.321833554389598" />
    </inertial>
    <visual>
      <origin
        xyz="0 0 0"
        rpy="0 0 0" />
      <geometry>
        <mesh
          filename="package://FullMech_Rep/meshes/drivetrain.STL" />
      </geometry>
      <material
        name="">
        <color
          rgba="0.792156862745098 0.819607843137255 0.933333333333333 1" />
      </material>
    </visual>
    <collision>
      <origin
        xyz="0 0 0"
        rpy="0 0 0" />
      <geometry>
        <mesh
          filename="package://FullMech_Rep/meshes/drivetrain.STL" />
      </geometry>
    </collision>
  </link>
  <link
    name="wheel1">
    <inertial>
      <origin
        xyz="-0.319999999965415 0.0253999997582183 0.186228402082417"
        rpy="0 0 0" />
      <mass
        value="1.22527899288124" />
      <inertia
        ixx="0.00598133533492436"
        ixy="-1.45951860387741E-09"
        ixz="8.92217485344828E-12"
        iyy="0.00598133741908379"
        iyz="-1.25414778505542E-11"
        izz="0.0109596153406548" />
    </inertial>
    <visual>
      <origin
        xyz="0 0 0"
        rpy="0 0 0" />
      <geometry>
        <mesh
          filename="package://FullMech_Rep/meshes/wheel1.STL" />
      </geometry>
      <material
        name="">
        <color
          rgba="1 1 1 1" />
      </material>
    </visual>
    <collision>
      <origin
        xyz="0 0 0"
        rpy="0 0 0" />
      <geometry>
        <mesh
          filename="package://FullMech_Rep/meshes/wheel1.STL" />
      </geometry>
    </collision>
  </link>
  <joint
    name="axle1"
    type="continuous">
    <origin
      xyz="0.16 0.115 0.19"
      rpy="0 0 0" />
    <parent
      link="drivetrain" />
    <child
      link="wheel1" />
    <axis
      xyz="0 0 1" />
  </joint>
  <link
    name="wheel2">
    <inertial>
      <origin
        xyz="-0.320000000029542 0.0254000002309468 -0.186228402082418"
        rpy="0 0 0" />
      <mass
        value="1.22527899288124" />
      <inertia
        ixx="0.00598133559564891"
        ixy="-8.33820335181087E-10"
        ixz="-3.93790599274392E-10"
        iyy="0.00598133491542502"
        iyz="-6.25138566540592E-10"
        izz="0.0109596137019381" />
    </inertial>
    <visual>
      <origin
        xyz="0 0 0"
        rpy="0 0 0" />
      <geometry>
        <mesh
          filename="package://FullMech_Rep/meshes/wheel2.STL" />
      </geometry>
      <material
        name="">
        <color
          rgba="1 1 1 1" />
      </material>
    </visual>
    <collision>
      <origin
        xyz="0 0 0"
        rpy="0 0 0" />
      <geometry>
        <mesh
          filename="package://FullMech_Rep/meshes/wheel2.STL" />
      </geometry>
    </collision>
  </link>
  <joint
    name="axle2"
    type="continuous">
    <origin
      xyz="0.16 0.115 -0.19"
      rpy="0 0 0" />
    <parent
      link="drivetrain" />
    <child
      link="wheel2" />
    <axis
      xyz="0 0 1" />
  </joint>
  <link
    name="wheel3">
    <inertial>
      <origin
        xyz="0.230000000246562 0.0253999997923425 -0.186228402082417"
        rpy="0 0 0" />
      <mass
        value="1.22527899288124" />
      <inertia
        ixx="0.00598133754268485"
        ixy="-1.36278916589831E-09"
        ixz="-1.81170744511866E-11"
        iyy="0.00598133521142073"
        iyz="2.24734516619137E-11"
        izz="0.0109596153407522" />
    </inertial>
    <visual>
      <origin
        xyz="0 0 0"
        rpy="0 0 0" />
      <geometry>
        <mesh
          filename="package://FullMech_Rep/meshes/wheel3.STL" />
      </geometry>
      <material
        name="">
        <color
          rgba="1 1 1 1" />
      </material>
    </visual>
    <collision>
      <origin
        xyz="0 0 0"
        rpy="0 0 0" />
      <geometry>
        <mesh
          filename="package://FullMech_Rep/meshes/wheel3.STL" />
      </geometry>
    </collision>
  </link>
  <joint
    name="axle3"
    type="continuous">
    <origin
      xyz="0.78 0.115 0.19"
      rpy="0 0 0" />
    <parent
      link="drivetrain" />
    <child
      link="wheel3" />
    <axis
      xyz="0 0 1" />
  </joint>
  <link
    name="wheel4">
    <inertial>
      <origin
        xyz="0.230000000034584 0.0253999997582191 0.186228402082418"
        rpy="0 0 0" />
      <mass
        value="1.22527899288124" />
      <inertia
        ixx="0.00598133533492436"
        ixy="-1.45951859994674E-09"
        ixz="8.92217439446231E-12"
        iyy="0.00598133741908381"
        iyz="-1.25414773881934E-11"
        izz="0.0109596153406548" />
    </inertial>
    <visual>
      <origin
        xyz="0 0 0"
        rpy="0 0 0" />
      <geometry>
        <mesh
          filename="package://FullMech_Rep/meshes/wheel4.STL" />
      </geometry>
      <material
        name="">
        <color
          rgba="1 1 1 1" />
      </material>
    </visual>
    <collision>
      <origin
        xyz="0 0 0"
        rpy="0 0 0" />
      <geometry>
        <mesh
          filename="package://FullMech_Rep/meshes/wheel4.STL" />
      </geometry>
    </collision>
  </link>
  <joint
    name="axle4"
    type="continuous">
    <origin
      xyz="0.78 0.115 -0.19"
      rpy="0 0 0" />
    <parent
      link="drivetrain" />
    <child
      link="wheel4" />
    <axis
      xyz="0 0 1" />
  </joint>
  <link
    name="storage">
    <inertial>
      <origin
        xyz="0.175 0.276401777374457 2.25713896662771E-16"
        rpy="0 0 0" />
      <mass
        value="0.248919999999999" />
      <inertia
        ixx="0.00162641116102266"
        ixy="7.96540095890137E-22"
        ixz="1.98679070880409E-19"
        iyy="0.00416733566666664"
        iyz="-5.53862670426238E-23"
        izz="0.00254119216102265" />
    </inertial>
    <visual>
      <origin
        xyz="0 0 0"
        rpy="0 0 0" />
      <geometry>
        <mesh
          filename="package://FullMech_Rep/meshes/storage.STL" />
      </geometry>
      <material
        name="">
        <color
          rgba="0.792156862745098 0.819607843137255 0.933333333333333 1" />
      </material>
    </visual>
    <collision>
      <origin
        xyz="0 0 0"
        rpy="0 0 0" />
      <geometry>
        <mesh
          filename="package://FullMech_Rep/meshes/storage.STL" />
      </geometry>
    </collision>
  </link>
  <joint
    name="scissor"
    type="prismatic">
    <origin
      xyz="0 0 0"
      rpy="0 0 0" />
    <parent
      link="drivetrain" />
    <child
      link="storage" />
    <axis
      xyz="0 1 0" />
    <limit
      lower="-0.1"
      upper="0.3"
      effort="5"
      velocity="0.25" />
  </joint>
  <link
    name="dispense">
    <inertial>
      <origin
        xyz="-0.316278340591933 0.317249948403711 -1.51759518433828E-16"
        rpy="0 0 0" />
      <mass
        value="0.490259886127997" />
      <inertia
        ixx="0.0077834363669299"
        ixy="-0.00266036642706342"
        ixz="9.31487295243375E-18"
        iyy="0.00957311492456408"
        iyz="1.16434978510516E-17"
        izz="0.00657647247964345" />
    </inertial>
    <visual>
      <origin
        xyz="0 0 0"
        rpy="0 0 0" />
      <geometry>
        <mesh
          filename="package://FullMech_Rep/meshes/dispense.STL" />
      </geometry>
      <material
        name="">
        <color
          rgba="0.792156862745098 0.819607843137255 0.933333333333333 1" />
      </material>
    </visual>
    <collision>
      <origin
        xyz="0 0 0"
        rpy="0 0 0" />
      <geometry>
        <mesh
          filename="package://FullMech_Rep/meshes/dispense.STL" />
      </geometry>
    </collision>
  </link>
  <joint
    name="dispense"
    type="revolute">
    <origin
      xyz="0.47 0.0896 0"
      rpy="0 0 0" />
    <parent
      link="storage" />
    <child
      link="dispense" />
    <axis
      xyz="0 0 -1" />
    <limit
      lower="0"
      upper="1.57"
      effort="5"
      velocity="0.25" />
  </joint>
  <link
    name="rotate_conv">
    <inertial>
      <origin
        xyz="0.267944768013426 0.133655983183746 1.2975675472875E-15"
        rpy="0 0 0" />
      <mass
        value="4.12035499957539" />
      <inertia
        ixx="0.504951827564745"
        ixy="0.155266647555281"
        ixz="-2.61309664227952E-16"
        iyy="0.0598724883705849"
        iyz="8.55503276726843E-16"
        izz="0.547695583840302" />
    </inertial>
    <visual>
      <origin
        xyz="0 0 0"
        rpy="0 0 0" />
      <geometry>
        <mesh
          filename="package://FullMech_Rep/meshes/rotate_conv.STL" />
      </geometry>
      <material
        name="">
        <color
          rgba="0.792156862745098 0.819607843137255 0.933333333333333 1" />
      </material>
    </visual>
    <collision>
      <origin
        xyz="0 0 0"
        rpy="0 0 0" />
      <geometry>
        <mesh
          filename="package://FullMech_Rep/meshes/rotate_conv.STL" />
      </geometry>
    </collision>
  </link>
  <joint
    name="rotate"
    type="revolute">
    <origin
      xyz="0.47 0.0896 0"
      rpy="0 0 0" />
    <parent
      link="drivetrain" />
    <child
      link="rotate_conv" />
    <axis
      xyz="0 0 1" />
    <limit
      lower="0.384"
      upper="1.309"
      effort="5"
      velocity="0.25" />
  </joint>
  <link
    name="translation">
    <inertial>
      <origin
        xyz="0.737944768013426 0.223255983183746 1.29675086879862E-15"
        rpy="0 0 0" />
      <mass
        value="4.12035499957539" />
      <inertia
        ixx="0.504951827564745"
        ixy="0.155266647555281"
        ixz="-2.61524946412685E-16"
        iyy="0.0598724883705849"
        iyz="8.581708096151E-16"
        izz="0.547695583840302" />
    </inertial>
    <visual>
      <origin
        xyz="0 0 0"
        rpy="0 0 0" />
      <geometry>
        <mesh
          filename="package://FullMech_Rep/meshes/translation.STL" />
      </geometry>
      <material
        name="">
        <color
          rgba="0.792156862745098 0.819607843137255 0.933333333333333 1" />
      </material>
    </visual>
    <collision>
      <origin
        xyz="0 0 0"
        rpy="0 0 0" />
      <geometry>
        <mesh
          filename="package://FullMech_Rep/meshes/translation.STL" />
      </geometry>
    </collision>
  </link>
  <joint
    name="rack"
    type="prismatic">
    <origin
      xyz="-0.47 -0.0896 0"
      rpy="0 0 0" />
    <parent
      link="rotate_conv" />
    <child
      link="translation" />
    <axis
      xyz="-0.2999 0.95397 0" />
    <limit
      lower="-0.5"
      upper="0.0"
      effort="5"
      velocity="0.25" />
  </joint>
</robot>